<?xml version="1.0" ?>
<robot name="">
	<link name="mount_base_link">
		<inertial>
			<origin rpy="0.00000 -0.00000 0.00000" xyz="0.00000 0.00000 0.00000"/>
			<mass value="0.00000"/>
			<inertia ixx="0.00000" ixy="0" ixz="0" iyy="0.00000" iyz="0" izz="0.00000"/>
		</inertial>
	</link>
	<link name="link_x">
		<inertial>
			<origin rpy="0.00000 -0.00000 0.00000" xyz="0.00000 0.00000 0.00000"/>
			<mass value="0.00000"/>
			<inertia ixx="0.00000" ixy="0" ixz="0" iyy="0.00000" iyz="0" izz="0.00000"/>
		</inertial>
	</link>
	<link name="link_y">
		<inertial>
			<origin rpy="0.00000 -0.00000 0.00000" xyz="0.00000 0.00000 0.00000"/>
			<mass value="0.00000"/>
			<inertia ixx="0.00000" ixy="0" ixz="0" iyy="0.00000" iyz="0" izz="0.00000"/>
		</inertial>
	</link>
	<link name="link_z">
		<inertial>
			<origin rpy="0.00000 -0.00000 0.00000" xyz="0.00000 0.00000 0.00000"/>
			<mass value="0.00000"/>
			<inertia ixx="0.00000" ixy="0" ixz="0" iyy="0.00000" iyz="0" izz="0.00000"/>
		</inertial>
	</link>
	<link name="link_xy">
		<inertial>
			<origin rpy="0.00000 -0.00000 0.00000" xyz="0.00000 0.00000 0.00000"/>
			<mass value="0.00000"/>
			<inertia ixx="0.00000" ixy="0" ixz="0" iyy="0.00000" iyz="0" izz="0.00000"/>
		</inertial>
	</link>
	<link name="link_yz">
		<inertial>
			<origin rpy="0.00000 -0.00000 0.00000" xyz="0.00000 0.00000 0.00000"/>
			<mass value="0.00000"/>
			<inertia ixx="0.00000" ixy="0" ixz="0" iyy="0.00000" iyz="0" izz="0.00000"/>
		</inertial>
	</link>
	<link name="mount_link">
		<inertial>
			<origin rpy="0.00000 -0.00000 0.00000" xyz="0.00000 0.00000 0.00000"/>
			<mass value="0.50000"/>
			<inertia ixx="0.00000" ixy="0" ixz="0" iyy="0.00000" iyz="0" izz="0.00000"/>
		</inertial>
	</link>
	<link name="base_link">
		<inertial>
			<origin rpy="0.00000 -0.00000 0.00000" xyz="0.00000 0.00000 0.00000"/>
			<mass value="0.00000"/>
			<inertia ixx="0.00000" ixy="0" ixz="0" iyy="0.00000" iyz="0" izz="0.00000"/>
		</inertial>
	</link>
	<link name="Palm">
		<inertial>
			<origin rpy="0.00000 -0.00000 0.00000" xyz="0.04101 -0.01851 -0.00250"/>
			<mass value="0.10000"/>
			<inertia ixx="0.00007" ixy="0" ixz="0" iyy="0.00012" iyz="0" izz="0.00018"/>
		</inertial>
		<visual>
			<origin rpy="0.00000 -0.00000 0.00000" xyz="0.00000 0.00000 0.00000"/>
			<geometry>
				<mesh filename="/home/omnisky/GraspIt2URDF/data/hand2/Palm.stl" scale="0.00100 0.00100 0.00100"/>
			</geometry>
			<material name="mat_0_0">
				<color rgba="1.00000 1.00000 1.00000 1.00000" />
			</material>
		</visual>
		<collision>
			<origin rpy="0.00000 -0.00000 0.00000" xyz="0.00000 0.00000 0.00000"/>
			<geometry>
				<mesh filename="/home/omnisky/GraspIt2URDF/data/hand2/Palm.stl" scale="0.00100 0.00100 0.00100"/>
			</geometry>
		</collision>
	</link>
	<link name="[LF_Meta3Theta]">
		<inertial>
			<origin rpy="0.00000 -0.00000 0.00000" xyz="0.00000 0.00000 0.00000"/>
			<mass value="0.00000"/>
			<inertia ixx="0.00000" ixy="0" ixz="0" iyy="0.00000" iyz="0" izz="0.00000"/>
		</inertial>
	</link>
	<link name="LF_Meta3">
		<inertial>
			<origin rpy="0.00000 -0.00000 0.00000" xyz="-0.01942 0.02372 -0.00041"/>
			<mass value="0.20000"/>
			<inertia ixx="0.00009" ixy="0" ixz="0" iyy="0.00007" iyz="0" izz="0.00014"/>
		</inertial>
		<visual>
			<origin rpy="0.00000 -0.00000 0.00000" xyz="0.00000 0.00000 0.00000"/>
			<geometry>
				<mesh filename="/home/omnisky/GraspIt2URDF/data/hand2/LF_Meta3.stl" scale="0.00100 0.00100 0.00100"/>
			</geometry>
			<material name="mat_2_0">
				<color rgba="1.00000 1.00000 1.00000 1.00000" />
			</material>
		</visual>
		<collision>
			<origin rpy="0.00000 -0.00000 0.00000" xyz="0.00000 0.00000 0.00000"/>
			<geometry>
				<mesh filename="/home/omnisky/GraspIt2URDF/data/hand2/LF_Meta3.stl" scale="0.00100 0.00100 0.00100"/>
			</geometry>
		</collision>
	</link>
	<link name="[Knuckle0Theta]">
		<inertial>
			<origin rpy="0.00000 -0.00000 0.00000" xyz="0.00000 0.00000 0.00000"/>
			<mass value="0.00000"/>
			<inertia ixx="0.00000" ixy="0" ixz="0" iyy="0.00000" iyz="0" izz="0.00000"/>
		</inertial>
	</link>
	<link name="Knuckle0">
		<inertial>
			<origin rpy="0.00000 -0.00000 0.00000" xyz="-0.00023 -0.00034 -0.00052"/>
			<mass value="0.10000"/>
			<inertia ixx="0.00001" ixy="0" ixz="0" iyy="0.00001" iyz="0" izz="0.00001"/>
		</inertial>
		<visual>
			<origin rpy="0.00000 -0.00000 0.00000" xyz="0.00000 0.00000 0.00000"/>
			<geometry>
				<mesh filename="/home/omnisky/GraspIt2URDF/data/hand2/Knuckle0.stl" scale="0.00100 0.00100 0.00100"/>
			</geometry>
			<material name="mat_4_0">
				<color rgba="1.00000 1.00000 1.00000 1.00000" />
			</material>
		</visual>
		<collision>
			<origin rpy="0.00000 -0.00000 0.00000" xyz="0.00000 0.00000 0.00000"/>
			<geometry>
				<mesh filename="/home/omnisky/GraspIt2URDF/data/hand2/Knuckle0.stl" scale="0.00100 0.00100 0.00100"/>
			</geometry>
		</collision>
	</link>
	<link name="[F_Prox0Theta]">
		<inertial>
			<origin rpy="0.00000 -0.00000 0.00000" xyz="0.00000 0.00000 0.00000"/>
			<mass value="0.00000"/>
			<inertia ixx="0.00000" ixy="0" ixz="0" iyy="0.00000" iyz="0" izz="0.00000"/>
		</inertial>
	</link>
	<link name="F_Prox0">
		<inertial>
			<origin rpy="0.00000 -0.00000 0.00000" xyz="-0.01948 -0.00002 -0.00055"/>
			<mass value="0.10000"/>
			<inertia ixx="0.00001" ixy="0" ixz="0" iyy="0.00004" iyz="0" izz="0.00004"/>
		</inertial>
		<visual>
			<origin rpy="0.00000 -0.00000 0.00000" xyz="0.00000 0.00000 0.00000"/>
			<geometry>
				<mesh filename="/home/omnisky/GraspIt2URDF/data/hand2/F_Prox0.stl" scale="0.00100 0.00100 0.00100"/>
			</geometry>
			<material name="mat_6_0">
				<color rgba="1.00000 1.00000 1.00000 1.00000" />
			</material>
		</visual>
		<collision>
			<origin rpy="0.00000 -0.00000 0.00000" xyz="0.00000 0.00000 0.00000"/>
			<geometry>
				<mesh filename="/home/omnisky/GraspIt2URDF/data/hand2/F_Prox0.stl" scale="0.00100 0.00100 0.00100"/>
			</geometry>
		</collision>
	</link>
	<link name="[F_Middle0Theta]">
		<inertial>
			<origin rpy="0.00000 -0.00000 0.00000" xyz="0.00000 0.00000 0.00000"/>
			<mass value="0.00000"/>
			<inertia ixx="0.00000" ixy="0" ixz="0" iyy="0.00000" iyz="0" izz="0.00000"/>
		</inertial>
	</link>
	<link name="F_Middle0">
		<inertial>
			<origin rpy="0.00000 -0.00000 0.00000" xyz="-0.01351 0.00004 -0.00001"/>
			<mass value="0.10000"/>
			<inertia ixx="0.00001" ixy="0" ixz="0" iyy="0.00002" iyz="0" izz="0.00002"/>
		</inertial>
		<visual>
			<origin rpy="0.00000 -0.00000 0.00000" xyz="0.00000 0.00000 0.00000"/>
			<geometry>
				<mesh filename="/home/omnisky/GraspIt2URDF/data/hand2/F_Middle0.stl" scale="0.00100 0.00100 0.00100"/>
			</geometry>
			<material name="mat_8_0">
				<color rgba="1.00000 1.00000 1.00000 1.00000" />
			</material>
		</visual>
		<collision>
			<origin rpy="0.00000 -0.00000 0.00000" xyz="0.00000 0.00000 0.00000"/>
			<geometry>
				<mesh filename="/home/omnisky/GraspIt2URDF/data/hand2/F_Middle0.stl" scale="0.00100 0.00100 0.00100"/>
			</geometry>
		</collision>
	</link>
	<link name="[F_Distal0Theta]">
		<inertial>
			<origin rpy="0.00000 -0.00000 0.00000" xyz="0.00000 0.00000 0.00000"/>
			<mass value="0.00000"/>
			<inertia ixx="0.00000" ixy="0" ixz="0" iyy="0.00000" iyz="0" izz="0.00000"/>
		</inertial>
	</link>
	<link name="F_Distal0">
		<inertial>
			<origin rpy="0.00000 -0.00000 0.00000" xyz="-0.01424 0.00005 -0.00001"/>
			<mass value="0.10000"/>
			<inertia ixx="0.00001" ixy="0" ixz="0" iyy="0.00001" iyz="0" izz="0.00001"/>
		</inertial>
		<visual>
			<origin rpy="0.00000 -0.00000 0.00000" xyz="0.00000 0.00000 0.00000"/>
			<geometry>
				<mesh filename="/home/omnisky/GraspIt2URDF/data/hand2/F_Distal0.stl" scale="0.00100 0.00100 0.00100"/>
			</geometry>
			<material name="mat_10_0">
				<color rgba="1.00000 1.00000 1.00000 1.00000" />
			</material>
		</visual>
		<collision>
			<origin rpy="0.00000 -0.00000 0.00000" xyz="0.00000 0.00000 0.00000"/>
			<geometry>
				<mesh filename="/home/omnisky/GraspIt2URDF/data/hand2/F_Distal0.stl" scale="0.00100 0.00100 0.00100"/>
			</geometry>
		</collision>
	</link>
	<link name="[Knuckle1Theta]">
		<inertial>
			<origin rpy="0.00000 -0.00000 0.00000" xyz="0.00000 0.00000 0.00000"/>
			<mass value="0.00000"/>
			<inertia ixx="0.00000" ixy="0" ixz="0" iyy="0.00000" iyz="0" izz="0.00000"/>
		</inertial>
	</link>
	<link name="Knuckle1">
		<inertial>
			<origin rpy="0.00000 -0.00000 0.00000" xyz="-0.00023 -0.00034 -0.00052"/>
			<mass value="0.10000"/>
			<inertia ixx="0.00001" ixy="0" ixz="0" iyy="0.00001" iyz="0" izz="0.00001"/>
		</inertial>
		<visual>
			<origin rpy="0.00000 -0.00000 0.00000" xyz="0.00000 0.00000 0.00000"/>
			<geometry>
				<mesh filename="/home/omnisky/GraspIt2URDF/data/hand2/Knuckle1.stl" scale="0.00100 0.00100 0.00100"/>
			</geometry>
			<material name="mat_12_0">
				<color rgba="1.00000 1.00000 1.00000 1.00000" />
			</material>
		</visual>
		<collision>
			<origin rpy="0.00000 -0.00000 0.00000" xyz="0.00000 0.00000 0.00000"/>
			<geometry>
				<mesh filename="/home/omnisky/GraspIt2URDF/data/hand2/Knuckle1.stl" scale="0.00100 0.00100 0.00100"/>
			</geometry>
		</collision>
	</link>
	<link name="[F_Prox1Theta]">
		<inertial>
			<origin rpy="0.00000 -0.00000 0.00000" xyz="0.00000 0.00000 0.00000"/>
			<mass value="0.00000"/>
			<inertia ixx="0.00000" ixy="0" ixz="0" iyy="0.00000" iyz="0" izz="0.00000"/>
		</inertial>
	</link>
	<link name="F_Prox1">
		<inertial>
			<origin rpy="0.00000 -0.00000 0.00000" xyz="-0.01948 -0.00002 -0.00055"/>
			<mass value="0.10000"/>
			<inertia ixx="0.00001" ixy="0" ixz="0" iyy="0.00004" iyz="0" izz="0.00004"/>
		</inertial>
		<visual>
			<origin rpy="0.00000 -0.00000 0.00000" xyz="0.00000 0.00000 0.00000"/>
			<geometry>
				<mesh filename="/home/omnisky/GraspIt2URDF/data/hand2/F_Prox1.stl" scale="0.00100 0.00100 0.00100"/>
			</geometry>
			<material name="mat_14_0">
				<color rgba="1.00000 1.00000 1.00000 1.00000" />
			</material>
		</visual>
		<collision>
			<origin rpy="0.00000 -0.00000 0.00000" xyz="0.00000 0.00000 0.00000"/>
			<geometry>
				<mesh filename="/home/omnisky/GraspIt2URDF/data/hand2/F_Prox1.stl" scale="0.00100 0.00100 0.00100"/>
			</geometry>
		</collision>
	</link>
	<link name="[F_Middle1Theta]">
		<inertial>
			<origin rpy="0.00000 -0.00000 0.00000" xyz="0.00000 0.00000 0.00000"/>
			<mass value="0.00000"/>
			<inertia ixx="0.00000" ixy="0" ixz="0" iyy="0.00000" iyz="0" izz="0.00000"/>
		</inertial>
	</link>
	<link name="F_Middle1">
		<inertial>
			<origin rpy="0.00000 -0.00000 0.00000" xyz="-0.01351 0.00004 -0.00001"/>
			<mass value="0.10000"/>
			<inertia ixx="0.00001" ixy="0" ixz="0" iyy="0.00002" iyz="0" izz="0.00002"/>
		</inertial>
		<visual>
			<origin rpy="0.00000 -0.00000 0.00000" xyz="0.00000 0.00000 0.00000"/>
			<geometry>
				<mesh filename="/home/omnisky/GraspIt2URDF/data/hand2/F_Middle1.stl" scale="0.00100 0.00100 0.00100"/>
			</geometry>
			<material name="mat_16_0">
				<color rgba="1.00000 1.00000 1.00000 1.00000" />
			</material>
		</visual>
		<collision>
			<origin rpy="0.00000 -0.00000 0.00000" xyz="0.00000 0.00000 0.00000"/>
			<geometry>
				<mesh filename="/home/omnisky/GraspIt2URDF/data/hand2/F_Middle1.stl" scale="0.00100 0.00100 0.00100"/>
			</geometry>
		</collision>
	</link>
	<link name="[F_Distal1Theta]">
		<inertial>
			<origin rpy="0.00000 -0.00000 0.00000" xyz="0.00000 0.00000 0.00000"/>
			<mass value="0.00000"/>
			<inertia ixx="0.00000" ixy="0" ixz="0" iyy="0.00000" iyz="0" izz="0.00000"/>
		</inertial>
	</link>
	<link name="F_Distal1">
		<inertial>
			<origin rpy="0.00000 -0.00000 0.00000" xyz="-0.01424 0.00005 -0.00001"/>
			<mass value="0.10000"/>
			<inertia ixx="0.00001" ixy="0" ixz="0" iyy="0.00001" iyz="0" izz="0.00001"/>
		</inertial>
		<visual>
			<origin rpy="0.00000 -0.00000 0.00000" xyz="0.00000 0.00000 0.00000"/>
			<geometry>
				<mesh filename="/home/omnisky/GraspIt2URDF/data/hand2/F_Distal1.stl" scale="0.00100 0.00100 0.00100"/>
			</geometry>
			<material name="mat_18_0">
				<color rgba="1.00000 1.00000 1.00000 1.00000" />
			</material>
		</visual>
		<collision>
			<origin rpy="0.00000 -0.00000 0.00000" xyz="0.00000 0.00000 0.00000"/>
			<geometry>
				<mesh filename="/home/omnisky/GraspIt2URDF/data/hand2/F_Distal1.stl" scale="0.00100 0.00100 0.00100"/>
			</geometry>
		</collision>
	</link>
	<link name="[Knuckle2Theta]">
		<inertial>
			<origin rpy="0.00000 -0.00000 0.00000" xyz="0.00000 0.00000 0.00000"/>
			<mass value="0.00000"/>
			<inertia ixx="0.00000" ixy="0" ixz="0" iyy="0.00000" iyz="0" izz="0.00000"/>
		</inertial>
	</link>
	<link name="Knuckle2">
		<inertial>
			<origin rpy="0.00000 -0.00000 0.00000" xyz="-0.00023 -0.00034 -0.00052"/>
			<mass value="0.10000"/>
			<inertia ixx="0.00001" ixy="0" ixz="0" iyy="0.00001" iyz="0" izz="0.00001"/>
		</inertial>
		<visual>
			<origin rpy="0.00000 -0.00000 0.00000" xyz="0.00000 0.00000 0.00000"/>
			<geometry>
				<mesh filename="/home/omnisky/GraspIt2URDF/data/hand2/Knuckle2.stl" scale="0.00100 0.00100 0.00100"/>
			</geometry>
			<material name="mat_20_0">
				<color rgba="1.00000 1.00000 1.00000 1.00000" />
			</material>
		</visual>
		<collision>
			<origin rpy="0.00000 -0.00000 0.00000" xyz="0.00000 0.00000 0.00000"/>
			<geometry>
				<mesh filename="/home/omnisky/GraspIt2URDF/data/hand2/Knuckle2.stl" scale="0.00100 0.00100 0.00100"/>
			</geometry>
		</collision>
	</link>
	<link name="[F_Prox2Theta]">
		<inertial>
			<origin rpy="0.00000 -0.00000 0.00000" xyz="0.00000 0.00000 0.00000"/>
			<mass value="0.00000"/>
			<inertia ixx="0.00000" ixy="0" ixz="0" iyy="0.00000" iyz="0" izz="0.00000"/>
		</inertial>
	</link>
	<link name="F_Prox2">
		<inertial>
			<origin rpy="0.00000 -0.00000 0.00000" xyz="-0.01948 -0.00002 -0.00055"/>
			<mass value="0.10000"/>
			<inertia ixx="0.00001" ixy="0" ixz="0" iyy="0.00004" iyz="0" izz="0.00004"/>
		</inertial>
		<visual>
			<origin rpy="0.00000 -0.00000 0.00000" xyz="0.00000 0.00000 0.00000"/>
			<geometry>
				<mesh filename="/home/omnisky/GraspIt2URDF/data/hand2/F_Prox2.stl" scale="0.00100 0.00100 0.00100"/>
			</geometry>
			<material name="mat_22_0">
				<color rgba="1.00000 1.00000 1.00000 1.00000" />
			</material>
		</visual>
		<collision>
			<origin rpy="0.00000 -0.00000 0.00000" xyz="0.00000 0.00000 0.00000"/>
			<geometry>
				<mesh filename="/home/omnisky/GraspIt2URDF/data/hand2/F_Prox2.stl" scale="0.00100 0.00100 0.00100"/>
			</geometry>
		</collision>
	</link>
	<link name="[F_Middle2Theta]">
		<inertial>
			<origin rpy="0.00000 -0.00000 0.00000" xyz="0.00000 0.00000 0.00000"/>
			<mass value="0.00000"/>
			<inertia ixx="0.00000" ixy="0" ixz="0" iyy="0.00000" iyz="0" izz="0.00000"/>
		</inertial>
	</link>
	<link name="F_Middle2">
		<inertial>
			<origin rpy="0.00000 -0.00000 0.00000" xyz="-0.01351 0.00004 -0.00001"/>
			<mass value="0.10000"/>
			<inertia ixx="0.00001" ixy="0" ixz="0" iyy="0.00002" iyz="0" izz="0.00002"/>
		</inertial>
		<visual>
			<origin rpy="0.00000 -0.00000 0.00000" xyz="0.00000 0.00000 0.00000"/>
			<geometry>
				<mesh filename="/home/omnisky/GraspIt2URDF/data/hand2/F_Middle2.stl" scale="0.00100 0.00100 0.00100"/>
			</geometry>
			<material name="mat_24_0">
				<color rgba="1.00000 1.00000 1.00000 1.00000" />
			</material>
		</visual>
		<collision>
			<origin rpy="0.00000 -0.00000 0.00000" xyz="0.00000 0.00000 0.00000"/>
			<geometry>
				<mesh filename="/home/omnisky/GraspIt2URDF/data/hand2/F_Middle2.stl" scale="0.00100 0.00100 0.00100"/>
			</geometry>
		</collision>
	</link>
	<link name="[F_Distal2Theta]">
		<inertial>
			<origin rpy="0.00000 -0.00000 0.00000" xyz="0.00000 0.00000 0.00000"/>
			<mass value="0.00000"/>
			<inertia ixx="0.00000" ixy="0" ixz="0" iyy="0.00000" iyz="0" izz="0.00000"/>
		</inertial>
	</link>
	<link name="F_Distal2">
		<inertial>
			<origin rpy="0.00000 -0.00000 0.00000" xyz="-0.01424 0.00005 -0.00001"/>
			<mass value="0.10000"/>
			<inertia ixx="0.00001" ixy="0" ixz="0" iyy="0.00001" iyz="0" izz="0.00001"/>
		</inertial>
		<visual>
			<origin rpy="0.00000 -0.00000 0.00000" xyz="0.00000 0.00000 0.00000"/>
			<geometry>
				<mesh filename="/home/omnisky/GraspIt2URDF/data/hand2/F_Distal2.stl" scale="0.00100 0.00100 0.00100"/>
			</geometry>
			<material name="mat_26_0">
				<color rgba="1.00000 1.00000 1.00000 1.00000" />
			</material>
		</visual>
		<collision>
			<origin rpy="0.00000 -0.00000 0.00000" xyz="0.00000 0.00000 0.00000"/>
			<geometry>
				<mesh filename="/home/omnisky/GraspIt2URDF/data/hand2/F_Distal2.stl" scale="0.00100 0.00100 0.00100"/>
			</geometry>
		</collision>
	</link>
	<link name="[Knuckle3Theta]">
		<inertial>
			<origin rpy="0.00000 -0.00000 0.00000" xyz="0.00000 0.00000 0.00000"/>
			<mass value="0.00000"/>
			<inertia ixx="0.00000" ixy="0" ixz="0" iyy="0.00000" iyz="0" izz="0.00000"/>
		</inertial>
	</link>
	<link name="Knuckle3">
		<inertial>
			<origin rpy="0.00000 -0.00000 0.00000" xyz="-0.00023 -0.00034 -0.00052"/>
			<mass value="0.10000"/>
			<inertia ixx="0.00001" ixy="0" ixz="0" iyy="0.00001" iyz="0" izz="0.00001"/>
		</inertial>
		<visual>
			<origin rpy="0.00000 -0.00000 0.00000" xyz="0.00000 0.00000 0.00000"/>
			<geometry>
				<mesh filename="/home/omnisky/GraspIt2URDF/data/hand2/Knuckle3.stl" scale="0.00100 0.00100 0.00100"/>
			</geometry>
			<material name="mat_28_0">
				<color rgba="1.00000 1.00000 1.00000 1.00000" />
			</material>
		</visual>
		<collision>
			<origin rpy="0.00000 -0.00000 0.00000" xyz="0.00000 0.00000 0.00000"/>
			<geometry>
				<mesh filename="/home/omnisky/GraspIt2URDF/data/hand2/Knuckle3.stl" scale="0.00100 0.00100 0.00100"/>
			</geometry>
		</collision>
	</link>
	<link name="[F_Prox3Theta]">
		<inertial>
			<origin rpy="0.00000 -0.00000 0.00000" xyz="0.00000 0.00000 0.00000"/>
			<mass value="0.00000"/>
			<inertia ixx="0.00000" ixy="0" ixz="0" iyy="0.00000" iyz="0" izz="0.00000"/>
		</inertial>
	</link>
	<link name="F_Prox3">
		<inertial>
			<origin rpy="0.00000 -0.00000 0.00000" xyz="-0.01948 -0.00002 -0.00055"/>
			<mass value="0.10000"/>
			<inertia ixx="0.00001" ixy="0" ixz="0" iyy="0.00004" iyz="0" izz="0.00004"/>
		</inertial>
		<visual>
			<origin rpy="0.00000 -0.00000 0.00000" xyz="0.00000 0.00000 0.00000"/>
			<geometry>
				<mesh filename="/home/omnisky/GraspIt2URDF/data/hand2/F_Prox3.stl" scale="0.00100 0.00100 0.00100"/>
			</geometry>
			<material name="mat_30_0">
				<color rgba="1.00000 1.00000 1.00000 1.00000" />
			</material>
		</visual>
		<collision>
			<origin rpy="0.00000 -0.00000 0.00000" xyz="0.00000 0.00000 0.00000"/>
			<geometry>
				<mesh filename="/home/omnisky/GraspIt2URDF/data/hand2/F_Prox3.stl" scale="0.00100 0.00100 0.00100"/>
			</geometry>
		</collision>
	</link>
	<link name="[F_Middle3Theta]">
		<inertial>
			<origin rpy="0.00000 -0.00000 0.00000" xyz="0.00000 0.00000 0.00000"/>
			<mass value="0.00000"/>
			<inertia ixx="0.00000" ixy="0" ixz="0" iyy="0.00000" iyz="0" izz="0.00000"/>
		</inertial>
	</link>
	<link name="F_Middle3">
		<inertial>
			<origin rpy="0.00000 -0.00000 0.00000" xyz="-0.01351 0.00004 -0.00001"/>
			<mass value="0.10000"/>
			<inertia ixx="0.00001" ixy="0" ixz="0" iyy="0.00002" iyz="0" izz="0.00002"/>
		</inertial>
		<visual>
			<origin rpy="0.00000 -0.00000 0.00000" xyz="0.00000 0.00000 0.00000"/>
			<geometry>
				<mesh filename="/home/omnisky/GraspIt2URDF/data/hand2/F_Middle3.stl" scale="0.00100 0.00100 0.00100"/>
			</geometry>
			<material name="mat_32_0">
				<color rgba="1.00000 1.00000 1.00000 1.00000" />
			</material>
		</visual>
		<collision>
			<origin rpy="0.00000 -0.00000 0.00000" xyz="0.00000 0.00000 0.00000"/>
			<geometry>
				<mesh filename="/home/omnisky/GraspIt2URDF/data/hand2/F_Middle3.stl" scale="0.00100 0.00100 0.00100"/>
			</geometry>
		</collision>
	</link>
	<link name="[F_Distal3Theta]">
		<inertial>
			<origin rpy="0.00000 -0.00000 0.00000" xyz="0.00000 0.00000 0.00000"/>
			<mass value="0.00000"/>
			<inertia ixx="0.00000" ixy="0" ixz="0" iyy="0.00000" iyz="0" izz="0.00000"/>
		</inertial>
	</link>
	<link name="F_Distal3">
		<inertial>
			<origin rpy="0.00000 -0.00000 0.00000" xyz="-0.01424 0.00005 -0.00001"/>
			<mass value="0.10000"/>
			<inertia ixx="0.00001" ixy="0" ixz="0" iyy="0.00001" iyz="0" izz="0.00001"/>
		</inertial>
		<visual>
			<origin rpy="0.00000 -0.00000 0.00000" xyz="0.00000 0.00000 0.00000"/>
			<geometry>
				<mesh filename="/home/omnisky/GraspIt2URDF/data/hand2/F_Distal3.stl" scale="0.00100 0.00100 0.00100"/>
			</geometry>
			<material name="mat_34_0">
				<color rgba="1.00000 1.00000 1.00000 1.00000" />
			</material>
		</visual>
		<collision>
			<origin rpy="0.00000 -0.00000 0.00000" xyz="0.00000 0.00000 0.00000"/>
			<geometry>
				<mesh filename="/home/omnisky/GraspIt2URDF/data/hand2/F_Distal3.stl" scale="0.00100 0.00100 0.00100"/>
			</geometry>
		</collision>
	</link>
	<link name="[TH_Proximal_0Theta]">
		<inertial>
			<origin rpy="0.00000 -0.00000 0.00000" xyz="0.00000 0.00000 0.00000"/>
			<mass value="0.00000"/>
			<inertia ixx="0.00000" ixy="0" ixz="0" iyy="0.00000" iyz="0" izz="0.00000"/>
		</inertial>
	</link>
	<link name="TH_Proximal_0">
		<inertial>
			<origin rpy="0.00000 -0.00000 0.00000" xyz="0.00000 0.00000 0.00000"/>
			<mass value="0.00000"/>
			<inertia ixx="0.00000" ixy="0" ixz="0" iyy="0.00000" iyz="0" izz="0.00000"/>
		</inertial>
	</link>
	<link name="[TH_ProximalTheta]">
		<inertial>
			<origin rpy="0.00000 -0.00000 0.00000" xyz="0.00000 0.00000 0.00000"/>
			<mass value="0.00000"/>
			<inertia ixx="0.00000" ixy="0" ixz="0" iyy="0.00000" iyz="0" izz="0.00000"/>
		</inertial>
	</link>
	<link name="TH_Proximal">
		<inertial>
			<origin rpy="0.00000 -0.00000 0.00000" xyz="-0.02195 0.00004 0.00004"/>
			<mass value="0.10000"/>
			<inertia ixx="0.00002" ixy="0" ixz="0" iyy="0.00005" iyz="0" izz="0.00005"/>
		</inertial>
		<visual>
			<origin rpy="0.00000 -0.00000 0.00000" xyz="0.00000 0.00000 0.00000"/>
			<geometry>
				<mesh filename="/home/omnisky/GraspIt2URDF/data/hand2/TH_Proximal.stl" scale="0.00100 0.00100 0.00100"/>
			</geometry>
			<material name="mat_38_0">
				<color rgba="1.00000 1.00000 1.00000 1.00000" />
			</material>
		</visual>
		<collision>
			<origin rpy="0.00000 -0.00000 0.00000" xyz="0.00000 0.00000 0.00000"/>
			<geometry>
				<mesh filename="/home/omnisky/GraspIt2URDF/data/hand2/TH_Proximal.stl" scale="0.00100 0.00100 0.00100"/>
			</geometry>
		</collision>
	</link>
	<link name="[TH_Middle_0Theta]">
		<inertial>
			<origin rpy="0.00000 -0.00000 0.00000" xyz="0.00000 0.00000 0.00000"/>
			<mass value="0.00000"/>
			<inertia ixx="0.00000" ixy="0" ixz="0" iyy="0.00000" iyz="0" izz="0.00000"/>
		</inertial>
	</link>
	<link name="TH_Middle_0">
		<inertial>
			<origin rpy="0.00000 -0.00000 0.00000" xyz="0.00000 0.00000 0.00000"/>
			<mass value="0.00000"/>
			<inertia ixx="0.00000" ixy="0" ixz="0" iyy="0.00000" iyz="0" izz="0.00000"/>
		</inertial>
	</link>
	<link name="[TH_MiddleTheta]">
		<inertial>
			<origin rpy="0.00000 -0.00000 0.00000" xyz="0.00000 0.00000 0.00000"/>
			<mass value="0.00000"/>
			<inertia ixx="0.00000" ixy="0" ixz="0" iyy="0.00000" iyz="0" izz="0.00000"/>
		</inertial>
	</link>
	<link name="TH_Middle">
		<inertial>
			<origin rpy="0.00000 -0.00000 0.00000" xyz="-0.01669 0.00008 0.00000"/>
			<mass value="0.10000"/>
			<inertia ixx="0.00001" ixy="0" ixz="0" iyy="0.00003" iyz="0" izz="0.00003"/>
		</inertial>
		<visual>
			<origin rpy="0.00000 -0.00000 0.00000" xyz="0.00000 0.00000 0.00000"/>
			<geometry>
				<mesh filename="/home/omnisky/GraspIt2URDF/data/hand2/TH_Middle.stl" scale="0.00100 0.00100 0.00100"/>
			</geometry>
			<material name="mat_42_0">
				<color rgba="1.00000 1.00000 1.00000 1.00000" />
			</material>
		</visual>
		<collision>
			<origin rpy="0.00000 -0.00000 0.00000" xyz="0.00000 0.00000 0.00000"/>
			<geometry>
				<mesh filename="/home/omnisky/GraspIt2URDF/data/hand2/TH_Middle.stl" scale="0.00100 0.00100 0.00100"/>
			</geometry>
		</collision>
	</link>
	<link name="[TH_DistalTheta]">
		<inertial>
			<origin rpy="0.00000 -0.00000 0.00000" xyz="0.00000 0.00000 0.00000"/>
			<mass value="0.00000"/>
			<inertia ixx="0.00000" ixy="0" ixz="0" iyy="0.00000" iyz="0" izz="0.00000"/>
		</inertial>
	</link>
	<link name="TH_Distal">
		<inertial>
			<origin rpy="0.00000 -0.00000 0.00000" xyz="-0.01839 -0.00076 0.00001"/>
			<mass value="0.10000"/>
			<inertia ixx="0.00001" ixy="0" ixz="0" iyy="0.00002" iyz="0" izz="0.00002"/>
		</inertial>
		<visual>
			<origin rpy="0.00000 -0.00000 0.00000" xyz="0.00000 0.00000 0.00000"/>
			<geometry>
				<mesh filename="/home/omnisky/GraspIt2URDF/data/hand2/TH_Distal.stl" scale="0.00100 0.00100 0.00100"/>
			</geometry>
			<material name="mat_44_0">
				<color rgba="1.00000 1.00000 1.00000 1.00000" />
			</material>
		</visual>
		<collision>
			<origin rpy="0.00000 -0.00000 0.00000" xyz="0.00000 0.00000 0.00000"/>
			<geometry>
				<mesh filename="/home/omnisky/GraspIt2URDF/data/hand2/TH_Distal.stl" scale="0.00100 0.00100 0.00100"/>
			</geometry>
		</collision>
	</link>
	<joint name="joint_x" type="prismatic">
		<parent link="mount_base_link"/>
		<child link="link_x"/>
		<limit effort="1000.0" lower="-1000.00000" upper="1000.00000" velocity="10"/>
		<dynamics damping="1.0" friction="0.0001"/>
		<origin rpy="0.00000 -0.00000 0.00000" xyz="0.00000 0.00000 0.00000"/>
		<axis xyz="1.00000 0.00000 0.00000"/>
	</joint>
	<joint name="joint_y" type="prismatic">
		<parent link="link_x"/>
		<child link="link_y"/>
		<limit effort="1000.0" lower="-1000.00000" upper="1000.00000" velocity="10"/>
		<dynamics damping="1.0" friction="0.0001"/>
		<origin rpy="0.00000 -0.00000 0.00000" xyz="0.00000 0.00000 0.00000"/>
		<axis xyz="0.00000 1.00000 0.00000"/>
	</joint>
	<joint name="joint_z" type="prismatic">
		<parent link="link_y"/>
		<child link="link_z"/>
		<limit effort="1000.0" lower="-1000.00000" upper="1000.00000" velocity="10"/>
		<dynamics damping="1.0" friction="0.0001"/>
		<origin rpy="0.00000 -0.00000 0.00000" xyz="0.00000 0.00000 0.00000"/>
		<axis xyz="0.00000 0.00000 1.00000"/>
	</joint>
	<joint name="joint_revolute_1" type="revolute">
		<parent link="link_z"/>
		<child link="link_xy"/>
		<limit effort="1000.0" lower="-1000.00000" upper="1000.00000" velocity="10"/>
		<dynamics damping="1.0" friction="0.0001"/>
		<origin rpy="0.00000 -0.00000 0.00000" xyz="0.00000 0.00000 0.00000"/>
		<axis xyz="0.00000 0.00000 1.00000"/>
	</joint>
	<joint name="joint_revolute_2" type="revolute">
		<parent link="link_xy"/>
		<child link="link_yz"/>
		<limit effort="1000.0" lower="-1000.00000" upper="1000.00000" velocity="10"/>
		<dynamics damping="1.0" friction="0.0001"/>
		<origin rpy="0.00000 -0.00000 0.00000" xyz="0.00000 0.00000 0.00000"/>
		<axis xyz="0.00000 1.00000 0.00000"/>
	</joint>
	<joint name="joint_revolute_3" type="revolute">
		<parent link="link_yz"/>
		<child link="mount_link"/>
		<limit effort="1000.0" lower="-1000.00000" upper="1000.00000" velocity="10"/>
		<dynamics damping="1.0" friction="0.0001"/>
		<origin rpy="0.00000 -0.00000 0.00000" xyz="0.00000 0.00000 0.00000"/>
		<axis xyz="1.00000 0.00000 0.00000"/>
	</joint>
	<joint name="joint_mount_gripper" type="fixed">
		<parent link="mount_link"/>
		<child link="base_link"/>
		<limit effort="1000.0" lower="0.00000" upper="-1.00000" velocity="10"/>
		<dynamics damping="1.0" friction="0.0001"/>
		<origin rpy="0.00000 0.00000 0.00000" xyz="0.00000 0.00000 0.00000"/>
		<axis xyz="0.00000 0.00000 1.00000"/>
	</joint>
	<joint name="base_link_palm" type="fixed">
		<parent link="base_link"/>
		<child link="Palm"/>
		<limit effort="1000.0" lower="0.00000" upper="-1.00000" velocity="10"/>
		<dynamics damping="1.0" friction="0.0001"/>
		<origin rpy="0.00000 -0.00000 0.00000" xyz="0.00000 0.00000 0.00000"/>
		<axis xyz="0.00000 0.00000 0.00000"/>
	</joint>
	<joint name="Palm_[LF_Meta3Theta]" type="revolute">
		<parent link="Palm"/>
		<child link="[LF_Meta3Theta]"/>
		<limit effort="1000.0" lower="0.00000" upper="0.78540" velocity="10"/>
		<dynamics damping="1.0" friction="0.0001"/>
		<origin rpy="1.57080 -0.00000 0.95993" xyz="0.06360 -0.00775 0.00000"/>
		<axis xyz="0.00000 0.00000 1.00000"/>
	</joint>
	<joint name="[LF_Meta3Theta]_LF_Meta3" type="fixed">
		<parent link="[LF_Meta3Theta]"/>
		<child link="LF_Meta3"/>
		<limit effort="1000.0" lower="0.00000" upper="-1.00000" velocity="10"/>
		<dynamics damping="1.0" friction="0.0001"/>
		<origin rpy="-1.57080 0.00000 0.00000" xyz="0.03700 0.00000 0.00000"/>
		<axis xyz="0.00000 0.00000 0.00000"/>
	</joint>
	<joint name="LF_Meta3_[Knuckle0Theta]" type="revolute">
		<parent link="LF_Meta3"/>
		<child link="[Knuckle0Theta]"/>
		<limit effort="1000.0" lower="-0.26180" upper="0.26180" velocity="10"/>
		<dynamics damping="1.0" friction="0.0001"/>
		<origin rpy="0.00000 -0.00000 0.00000" xyz="0.00000 0.00000 0.00000"/>
		<axis xyz="0.00000 0.00000 1.00000"/>
	</joint>
	<joint name="[Knuckle0Theta]_Knuckle0" type="fixed">
		<parent link="[Knuckle0Theta]"/>
		<child link="Knuckle0"/>
		<limit effort="1000.0" lower="0.00000" upper="-1.00000" velocity="10"/>
		<dynamics damping="1.0" friction="0.0001"/>
		<origin rpy="1.57080 -0.00000 -0.95993" xyz="0.00000 0.00000 0.00000"/>
		<axis xyz="0.00000 0.00000 0.00000"/>
	</joint>
	<joint name="Knuckle0_[F_Prox0Theta]" type="revolute">
		<parent link="Knuckle0"/>
		<child link="[F_Prox0Theta]"/>
		<limit effort="1000.0" lower="-0.26180" upper="1.57080" velocity="10"/>
		<dynamics damping="1.0" friction="0.0001"/>
		<origin rpy="0.00000 -0.00000 0.00000" xyz="0.00000 0.00000 0.00000"/>
		<axis xyz="0.00000 0.00000 1.00000"/>
	</joint>
	<joint name="[F_Prox0Theta]_F_Prox0" type="fixed">
		<parent link="[F_Prox0Theta]"/>
		<child link="F_Prox0"/>
		<limit effort="1000.0" lower="0.00000" upper="-1.00000" velocity="10"/>
		<dynamics damping="1.0" friction="0.0001"/>
		<origin rpy="0.00000 -0.00000 0.00000" xyz="0.04500 0.00000 0.00000"/>
		<axis xyz="0.00000 0.00000 0.00000"/>
	</joint>
	<joint name="F_Prox0_[F_Middle0Theta]" type="revolute">
		<parent link="F_Prox0"/>
		<child link="[F_Middle0Theta]"/>
		<limit effort="1000.0" lower="0.00000" upper="1.57080" velocity="10"/>
		<dynamics damping="1.0" friction="0.0001"/>
		<origin rpy="0.00000 -0.00000 0.00000" xyz="0.00000 0.00000 0.00000"/>
		<axis xyz="0.00000 0.00000 1.00000"/>
	</joint>
	<joint name="[F_Middle0Theta]_F_Middle0" type="fixed">
		<parent link="[F_Middle0Theta]"/>
		<child link="F_Middle0"/>
		<limit effort="1000.0" lower="0.00000" upper="-1.00000" velocity="10"/>
		<dynamics damping="1.0" friction="0.0001"/>
		<origin rpy="0.00000 -0.00000 0.00000" xyz="0.02500 0.00000 0.00000"/>
		<axis xyz="0.00000 0.00000 0.00000"/>
	</joint>
	<joint name="F_Middle0_[F_Distal0Theta]" type="revolute">
		<parent link="F_Middle0"/>
		<child link="[F_Distal0Theta]"/>
		<limit effort="1000.0" lower="0.00000" upper="1.57080" velocity="10"/>
		<dynamics damping="1.0" friction="0.0001"/>
		<origin rpy="0.00000 -0.00000 0.00000" xyz="0.00000 0.00000 0.00000"/>
		<axis xyz="0.00000 0.00000 1.00000"/>
	</joint>
	<joint name="[F_Distal0Theta]_F_Distal0" type="fixed">
		<parent link="[F_Distal0Theta]"/>
		<child link="F_Distal0"/>
		<limit effort="1000.0" lower="0.00000" upper="-1.00000" velocity="10"/>
		<dynamics damping="1.0" friction="0.0001"/>
		<origin rpy="0.00000 -0.00000 0.00000" xyz="0.03000 0.00000 0.00000"/>
		<axis xyz="0.00000 0.00000 0.00000"/>
	</joint>
	<joint name="Palm_[Knuckle1Theta]" type="revolute">
		<parent link="Palm"/>
		<child link="[Knuckle1Theta]"/>
		<limit effort="1000.0" lower="-0.26180" upper="0.26180" velocity="10"/>
		<dynamics damping="1.0" friction="0.0001"/>
		<origin rpy="0.00000 -0.00000 0.95993" xyz="0.09200 0.00000 0.00000"/>
		<axis xyz="0.00000 0.00000 1.00000"/>
	</joint>
	<joint name="[Knuckle1Theta]_Knuckle1" type="fixed">
		<parent link="[Knuckle1Theta]"/>
		<child link="Knuckle1"/>
		<limit effort="1000.0" lower="0.00000" upper="-1.00000" velocity="10"/>
		<dynamics damping="1.0" friction="0.0001"/>
		<origin rpy="1.57080 -0.00000 -0.95993" xyz="0.00000 0.00000 0.00000"/>
		<axis xyz="0.00000 0.00000 0.00000"/>
	</joint>
	<joint name="Knuckle1_[F_Prox1Theta]" type="revolute">
		<parent link="Knuckle1"/>
		<child link="[F_Prox1Theta]"/>
		<limit effort="1000.0" lower="-0.26180" upper="1.57080" velocity="10"/>
		<dynamics damping="1.0" friction="0.0001"/>
		<origin rpy="0.00000 -0.00000 0.00000" xyz="0.00000 0.00000 0.00000"/>
		<axis xyz="0.00000 0.00000 1.00000"/>
	</joint>
	<joint name="[F_Prox1Theta]_F_Prox1" type="fixed">
		<parent link="[F_Prox1Theta]"/>
		<child link="F_Prox1"/>
		<limit effort="1000.0" lower="0.00000" upper="-1.00000" velocity="10"/>
		<dynamics damping="1.0" friction="0.0001"/>
		<origin rpy="0.00000 -0.00000 0.00000" xyz="0.04500 0.00000 0.00000"/>
		<axis xyz="0.00000 0.00000 0.00000"/>
	</joint>
	<joint name="F_Prox1_[F_Middle1Theta]" type="revolute">
		<parent link="F_Prox1"/>
		<child link="[F_Middle1Theta]"/>
		<limit effort="1000.0" lower="0.00000" upper="1.57080" velocity="10"/>
		<dynamics damping="1.0" friction="0.0001"/>
		<origin rpy="0.00000 -0.00000 0.00000" xyz="0.00000 0.00000 0.00000"/>
		<axis xyz="0.00000 0.00000 1.00000"/>
	</joint>
	<joint name="[F_Middle1Theta]_F_Middle1" type="fixed">
		<parent link="[F_Middle1Theta]"/>
		<child link="F_Middle1"/>
		<limit effort="1000.0" lower="0.00000" upper="-1.00000" velocity="10"/>
		<dynamics damping="1.0" friction="0.0001"/>
		<origin rpy="0.00000 -0.00000 0.00000" xyz="0.02500 0.00000 0.00000"/>
		<axis xyz="0.00000 0.00000 0.00000"/>
	</joint>
	<joint name="F_Middle1_[F_Distal1Theta]" type="revolute">
		<parent link="F_Middle1"/>
		<child link="[F_Distal1Theta]"/>
		<limit effort="1000.0" lower="0.00000" upper="1.57080" velocity="10"/>
		<dynamics damping="1.0" friction="0.0001"/>
		<origin rpy="0.00000 -0.00000 0.00000" xyz="0.00000 0.00000 0.00000"/>
		<axis xyz="0.00000 0.00000 1.00000"/>
	</joint>
	<joint name="[F_Distal1Theta]_F_Distal1" type="fixed">
		<parent link="[F_Distal1Theta]"/>
		<child link="F_Distal1"/>
		<limit effort="1000.0" lower="0.00000" upper="-1.00000" velocity="10"/>
		<dynamics damping="1.0" friction="0.0001"/>
		<origin rpy="0.00000 -0.00000 0.00000" xyz="0.03000 0.00000 0.00000"/>
		<axis xyz="0.00000 0.00000 0.00000"/>
	</joint>
	<joint name="Palm_[Knuckle2Theta]" type="revolute">
		<parent link="Palm"/>
		<child link="[Knuckle2Theta]"/>
		<limit effort="1000.0" lower="-0.26180" upper="0.26180" velocity="10"/>
		<dynamics damping="1.0" friction="0.0001"/>
		<origin rpy="0.00000 -0.00000 0.00000" xyz="0.09500 -0.02200 0.00100"/>
		<axis xyz="0.00000 0.00000 1.00000"/>
	</joint>
	<joint name="[Knuckle2Theta]_Knuckle2" type="fixed">
		<parent link="[Knuckle2Theta]"/>
		<child link="Knuckle2"/>
		<limit effort="1000.0" lower="0.00000" upper="-1.00000" velocity="10"/>
		<dynamics damping="1.0" friction="0.0001"/>
		<origin rpy="1.57080 -0.00000 0.00000" xyz="0.00000 0.00000 0.00000"/>
		<axis xyz="0.00000 0.00000 0.00000"/>
	</joint>
	<joint name="Knuckle2_[F_Prox2Theta]" type="revolute">
		<parent link="Knuckle2"/>
		<child link="[F_Prox2Theta]"/>
		<limit effort="1000.0" lower="-0.26180" upper="1.57080" velocity="10"/>
		<dynamics damping="1.0" friction="0.0001"/>
		<origin rpy="0.00000 -0.00000 0.00000" xyz="0.00000 0.00000 0.00000"/>
		<axis xyz="0.00000 0.00000 1.00000"/>
	</joint>
	<joint name="[F_Prox2Theta]_F_Prox2" type="fixed">
		<parent link="[F_Prox2Theta]"/>
		<child link="F_Prox2"/>
		<limit effort="1000.0" lower="0.00000" upper="-1.00000" velocity="10"/>
		<dynamics damping="1.0" friction="0.0001"/>
		<origin rpy="0.00000 -0.00000 0.00000" xyz="0.04500 0.00000 0.00000"/>
		<axis xyz="0.00000 0.00000 0.00000"/>
	</joint>
	<joint name="F_Prox2_[F_Middle2Theta]" type="revolute">
		<parent link="F_Prox2"/>
		<child link="[F_Middle2Theta]"/>
		<limit effort="1000.0" lower="0.00000" upper="1.57080" velocity="10"/>
		<dynamics damping="1.0" friction="0.0001"/>
		<origin rpy="0.00000 -0.00000 0.00000" xyz="0.00000 0.00000 0.00000"/>
		<axis xyz="0.00000 0.00000 1.00000"/>
	</joint>
	<joint name="[F_Middle2Theta]_F_Middle2" type="fixed">
		<parent link="[F_Middle2Theta]"/>
		<child link="F_Middle2"/>
		<limit effort="1000.0" lower="0.00000" upper="-1.00000" velocity="10"/>
		<dynamics damping="1.0" friction="0.0001"/>
		<origin rpy="0.00000 -0.00000 0.00000" xyz="0.02500 0.00000 0.00000"/>
		<axis xyz="0.00000 0.00000 0.00000"/>
	</joint>
	<joint name="F_Middle2_[F_Distal2Theta]" type="revolute">
		<parent link="F_Middle2"/>
		<child link="[F_Distal2Theta]"/>
		<limit effort="1000.0" lower="0.00000" upper="1.57080" velocity="10"/>
		<dynamics damping="1.0" friction="0.0001"/>
		<origin rpy="0.00000 -0.00000 0.00000" xyz="0.00000 0.00000 0.00000"/>
		<axis xyz="0.00000 0.00000 1.00000"/>
	</joint>
	<joint name="[F_Distal2Theta]_F_Distal2" type="fixed">
		<parent link="[F_Distal2Theta]"/>
		<child link="F_Distal2"/>
		<limit effort="1000.0" lower="0.00000" upper="-1.00000" velocity="10"/>
		<dynamics damping="1.0" friction="0.0001"/>
		<origin rpy="0.00000 -0.00000 0.00000" xyz="0.03000 0.00000 0.00000"/>
		<axis xyz="0.00000 0.00000 0.00000"/>
	</joint>
	<joint name="Palm_[Knuckle3Theta]" type="revolute">
		<parent link="Palm"/>
		<child link="[Knuckle3Theta]"/>
		<limit effort="1000.0" lower="-0.26180" upper="0.26180" velocity="10"/>
		<dynamics damping="1.0" friction="0.0001"/>
		<origin rpy="0.00000 -0.00000 0.00000" xyz="0.09100 -0.04400 0.00200"/>
		<axis xyz="0.00000 0.00000 1.00000"/>
	</joint>
	<joint name="[Knuckle3Theta]_Knuckle3" type="fixed">
		<parent link="[Knuckle3Theta]"/>
		<child link="Knuckle3"/>
		<limit effort="1000.0" lower="0.00000" upper="-1.00000" velocity="10"/>
		<dynamics damping="1.0" friction="0.0001"/>
		<origin rpy="1.57080 -0.00000 0.00000" xyz="0.00000 0.00000 0.00000"/>
		<axis xyz="0.00000 0.00000 0.00000"/>
	</joint>
	<joint name="Knuckle3_[F_Prox3Theta]" type="revolute">
		<parent link="Knuckle3"/>
		<child link="[F_Prox3Theta]"/>
		<limit effort="1000.0" lower="-0.26180" upper="1.57080" velocity="10"/>
		<dynamics damping="1.0" friction="0.0001"/>
		<origin rpy="0.00000 -0.00000 0.00000" xyz="0.00000 0.00000 0.00000"/>
		<axis xyz="0.00000 0.00000 1.00000"/>
	</joint>
	<joint name="[F_Prox3Theta]_F_Prox3" type="fixed">
		<parent link="[F_Prox3Theta]"/>
		<child link="F_Prox3"/>
		<limit effort="1000.0" lower="0.00000" upper="-1.00000" velocity="10"/>
		<dynamics damping="1.0" friction="0.0001"/>
		<origin rpy="0.00000 -0.00000 0.00000" xyz="0.04500 0.00000 0.00000"/>
		<axis xyz="0.00000 0.00000 0.00000"/>
	</joint>
	<joint name="F_Prox3_[F_Middle3Theta]" type="revolute">
		<parent link="F_Prox3"/>
		<child link="[F_Middle3Theta]"/>
		<limit effort="1000.0" lower="0.00000" upper="1.57080" velocity="10"/>
		<dynamics damping="1.0" friction="0.0001"/>
		<origin rpy="0.00000 -0.00000 0.00000" xyz="0.00000 0.00000 0.00000"/>
		<axis xyz="0.00000 0.00000 1.00000"/>
	</joint>
	<joint name="[F_Middle3Theta]_F_Middle3" type="fixed">
		<parent link="[F_Middle3Theta]"/>
		<child link="F_Middle3"/>
		<limit effort="1000.0" lower="0.00000" upper="-1.00000" velocity="10"/>
		<dynamics damping="1.0" friction="0.0001"/>
		<origin rpy="0.00000 -0.00000 0.00000" xyz="0.02500 0.00000 0.00000"/>
		<axis xyz="0.00000 0.00000 0.00000"/>
	</joint>
	<joint name="F_Middle3_[F_Distal3Theta]" type="revolute">
		<parent link="F_Middle3"/>
		<child link="[F_Distal3Theta]"/>
		<limit effort="1000.0" lower="0.00000" upper="1.57080" velocity="10"/>
		<dynamics damping="1.0" friction="0.0001"/>
		<origin rpy="0.00000 -0.00000 0.00000" xyz="0.00000 0.00000 0.00000"/>
		<axis xyz="0.00000 0.00000 1.00000"/>
	</joint>
	<joint name="[F_Distal3Theta]_F_Distal3" type="fixed">
		<parent link="[F_Distal3Theta]"/>
		<child link="F_Distal3"/>
		<limit effort="1000.0" lower="0.00000" upper="-1.00000" velocity="10"/>
		<dynamics damping="1.0" friction="0.0001"/>
		<origin rpy="0.00000 -0.00000 0.00000" xyz="0.03000 0.00000 0.00000"/>
		<axis xyz="0.00000 0.00000 0.00000"/>
	</joint>
	<joint name="Palm_[TH_Proximal_0Theta]" type="revolute">
		<parent link="Palm"/>
		<child link="[TH_Proximal_0Theta]"/>
		<limit effort="1000.0" lower="-1.04720" upper="1.04720" velocity="10"/>
		<dynamics damping="1.0" friction="0.0001"/>
		<origin rpy="0.00000 1.57080 -0.78540" xyz="0.02142 -0.03608 0.00800"/>
		<axis xyz="0.00000 0.00000 1.00000"/>
	</joint>
	<joint name="[TH_Proximal_0Theta]_TH_Proximal_0" type="fixed">
		<parent link="[TH_Proximal_0Theta]"/>
		<child link="TH_Proximal_0"/>
		<limit effort="1000.0" lower="0.00000" upper="-1.00000" velocity="10"/>
		<dynamics damping="1.0" friction="0.0001"/>
		<origin rpy="1.57080 -0.00000 0.00000" xyz="0.00000 0.00000 0.00000"/>
		<axis xyz="0.00000 0.00000 0.00000"/>
	</joint>
	<joint name="TH_Proximal_0_[TH_ProximalTheta]" type="revolute">
		<parent link="TH_Proximal_0"/>
		<child link="[TH_ProximalTheta]"/>
		<limit effort="1000.0" lower="0.00000" upper="1.22173" velocity="10"/>
		<dynamics damping="1.0" friction="0.0001"/>
		<origin rpy="0.00000 -0.00000 0.00000" xyz="0.00000 0.00000 0.00000"/>
		<axis xyz="0.00000 0.00000 1.00000"/>
	</joint>
	<joint name="[TH_ProximalTheta]_TH_Proximal" type="fixed">
		<parent link="[TH_ProximalTheta]"/>
		<child link="TH_Proximal"/>
		<limit effort="1000.0" lower="0.00000" upper="-1.00000" velocity="10"/>
		<dynamics damping="1.0" friction="0.0001"/>
		<origin rpy="-3.14159 -0.00000 1.57080" xyz="0.00000 0.03800 0.00000"/>
		<axis xyz="0.00000 0.00000 0.00000"/>
	</joint>
	<joint name="TH_Proximal_[TH_Middle_0Theta]" type="revolute">
		<parent link="TH_Proximal"/>
		<child link="[TH_Middle_0Theta]"/>
		<limit effort="1000.0" lower="-0.20944" upper="0.20944" velocity="10"/>
		<dynamics damping="1.0" friction="0.0001"/>
		<origin rpy="0.00000 -0.00000 0.00000" xyz="0.00000 0.00000 0.00000"/>
		<axis xyz="0.00000 0.00000 1.00000"/>
	</joint>
	<joint name="[TH_Middle_0Theta]_TH_Middle_0" type="fixed">
		<parent link="[TH_Middle_0Theta]"/>
		<child link="TH_Middle_0"/>
		<limit effort="1000.0" lower="0.00000" upper="-1.00000" velocity="10"/>
		<dynamics damping="1.0" friction="0.0001"/>
		<origin rpy="1.57080 -0.00000 0.00000" xyz="0.00000 0.00000 0.00000"/>
		<axis xyz="0.00000 0.00000 0.00000"/>
	</joint>
	<joint name="TH_Middle_0_[TH_MiddleTheta]" type="revolute">
		<parent link="TH_Middle_0"/>
		<child link="[TH_MiddleTheta]"/>
		<limit effort="1000.0" lower="-0.52360" upper="0.52360" velocity="10"/>
		<dynamics damping="1.0" friction="0.0001"/>
		<origin rpy="0.00000 -0.00000 0.00000" xyz="0.00000 0.00000 0.00000"/>
		<axis xyz="0.00000 0.00000 1.00000"/>
	</joint>
	<joint name="[TH_MiddleTheta]_TH_Middle" type="fixed">
		<parent link="[TH_MiddleTheta]"/>
		<child link="TH_Middle"/>
		<limit effort="1000.0" lower="0.00000" upper="-1.00000" velocity="10"/>
		<dynamics damping="1.0" friction="0.0001"/>
		<origin rpy="0.00000 -0.00000 0.00000" xyz="0.03200 0.00000 0.00000"/>
		<axis xyz="0.00000 0.00000 0.00000"/>
	</joint>
	<joint name="TH_Middle_[TH_DistalTheta]" type="revolute">
		<parent link="TH_Middle"/>
		<child link="[TH_DistalTheta]"/>
		<limit effort="1000.0" lower="0.00000" upper="1.57080" velocity="10"/>
		<dynamics damping="1.0" friction="0.0001"/>
		<origin rpy="0.00000 -0.00000 0.00000" xyz="0.00000 0.00000 0.00000"/>
		<axis xyz="0.00000 0.00000 1.00000"/>
	</joint>
	<joint name="[TH_DistalTheta]_TH_Distal" type="fixed">
		<parent link="[TH_DistalTheta]"/>
		<child link="TH_Distal"/>
		<limit effort="1000.0" lower="0.00000" upper="-1.00000" velocity="10"/>
		<dynamics damping="1.0" friction="0.0001"/>
		<origin rpy="0.00000 -0.00000 0.00000" xyz="0.03300 0.00000 0.00000"/>
		<axis xyz="0.00000 0.00000 0.00000"/>
	</joint>
</robot>
